Workbook

Sheet Lisez-moi
A1: TAKT — Backlog de référence, version 1.0
A2: Version 1.0 · 3 octobre 2026. Source des tickets : Backlog_TAKT_tickets.csv (séparateur « ; »).
A4: Lecture
A5: Chaque ticket cite les exigences de la spécification fonctionnelle (codes EX-…, colonne « Réf. SF ») et les sections de la spécification technique (colonne « Réf. ST »).
A6: Un ticket sans exigence est un ticket technique, de test ou un spike, justifié par la ST.
A7: Les totaux des feuilles Lots et Epics sont calculés par formule depuis la feuille Tickets.
A8: Les cellules Statut et Sprint de la feuille Tickets sont à renseigner par l'équipe.
A9: La matrice de traçabilité est générée par tools/verifier_coherence.py (TRACABILITE_TAKT.md).

Sheet Tickets
A1: ID | B1: Lot | C1: Epic ID | D1: Epic | E1: Type | F1: Titre | G1: Description | H1: Critères d'acceptation | I1: Réf. SF | J1: Réf. ST | K1: Profil | L1: Priorité | M1: Points | N1: Dépendances | O1: Statut | P1: Sprint
A2: L0-01 | B2: L0 | C2: E0.1 | D2: Monorepo & CI/CD | E2: Tâche technique | F2: Initialiser le monorepo | G2: Créer apps (web, api, worker) et packages (contracts, conflict-engine, charge-engine, engine-fet, design-tokens, db). | H2: - Arborescence conforme à ST §1.5 - Une commande unique lance lint, typecheck et build sur tous les paquets - TypeScript strict activé partout - Règles de dépendance entre modules vérifiées par le lint (un module n'importe que les interfaces des autres) | I2: EX-NFR-09 | J2: §1.5, §1.4 | K2: DEVOPS | L2: Must | M2: 3 | O2: Terminé
A3: L0-02 | B3: L0 | C3: E0.1 | D3: Monorepo & CI/CD | E3: Tâche technique | F3: Pipeline CI/CD et registre d'images privé | G3: Lint, typecheck, tests, build d'images publiées dans un registre privé interne, migrations, déploiement par environnement par scripts. | H3: - Une PR déclenche lint, typecheck, tests et build - Le scan des dépendances, des secrets et des images est exécuté - Les images sont publiées dans le registre privé interne - Un déploiement dev est automatique après merge | I3: EX-NFR-02 | J3: §5.5, §1.8 | K3: DEVOPS | L3: Must | M3: 5 | N3: L0-01 | O3: Terminé
A4: L0-03 | B4: L0 | C4: E0.1 | D4: Monorepo & CI/CD | E4: Tâche technique | F4: Paquet contracts (Zod + types OpenAPI) | G4: Schémas partagés front/back et génération des types clients. | H4: - Les schémas Zod sont importables par api et web - Les types clients sont générés depuis l'OpenAPI - Un changement de contrat casse le build si non répercuté | I4: — | J4: §3.1, §5.3 | K4: BACK | L4: Must | M4: 3 | N4: L0-01 | O4: Terminé
A5: L0-04 | B5: L0 | C5: E0.1 | D5: Monorepo & CI/CD | E5: Tâche technique | F5: Prisma initial et migrations SQL brutes | G5: Schéma d'amorçage (User, UserRole, RefreshToken, AuditLog), identifiants UUID, mécanisme de migrations --create-only, Testcontainers. | H5: - Les migrations s'appliquent sur une base vide en CI - Une migration SQL brute (index partiel, trigger) est rejouée avec succès - Tests d'intégration PostgreSQL via Testcontainers opérationnels - Les clés primaires sont des UUID et les codes fonctionnels sont distincts des identifiants techniques | I5: EX-DAT-01 | J5: §2.2, §2.4 | K5: BACK | L5: Must | M5: 5 | N5: L0-01 | O5: Terminé
A6: L0-05 | B6: L0 | C6: E0.1 | D6: Monorepo & CI/CD | E6: Tâche technique | F6: Intégration des tokens de conception | G6: Paquet design-tokens : génération des variables CSS depuis TAKT_design_tokens_v2_3_6.json (charte V2.3.6, clés d'état = codes API), configuration Tailwind, polices Sora, Inter et Black Ops One auto-hébergées, logo maître SVG, icônes métier SVG. | H6: - Les couleurs de l'interface proviennent exclusivement des variables CSS générées, sans valeur hexadécimale en dur hors du paquet - Aucune requête réseau externe pour les polices - Black Ops One n'est utilisée que pour la signature de marque « TAKT » ; le logo est toujours le SVG maître, jamais reconstruit en texte - OFL-Black-Ops-One.txt est conservé avec la police dans le dépôt et dans l'image web - Les couleurs d'état sont lues uniquement depuis states.*.*.text (texte) et states.*.*.color (icône, bordure) ; le lint interdit color en texte - Le contraste texte 4,5:1 et composant 3:1 est vérifié sur Ivory, Warm, Inset, Card et Elevated ; seul color.navigation_on_deep.text_disabled est exempté ; le build échoue en cas d'écart - Les icônes d'état référencées par les tokens existent dans lucide-react (version épinglée) ou dans le dossier icons/ ; un test échoue sinon | I6: EX-NFR-10 | J6: §0.1 | K6: FRONT | L6: Must | M6: 5 | N6: L0-01 | O6: Terminé
A7: L0-06 | B7: L0 | C7: E0.2 | D7: Infrastructure sur site | E7: Tâche technique | F7: Réseau et périmètre sur site | G7: Nginx en reverse proxy (TLS, limitation de débit), pare-feu, réseau de conteneurs interne, route sortante unique de l'API vers le SMTP. | H7: - Seul le port 443 de Nginx est exposé sur le réseau interne - API, worker et base accessibles uniquement depuis le réseau de conteneurs - La limitation de débit par IP est active - Le worker n'a aucune route sortante ; l'API n'a que la route vers l'hôte et le port SMTP | I7: EX-NFR-01 | J7: §5.3, §1.8 | K7: DEVOPS | L7: Must | M7: 8 | N7: L0-01 | O7: Terminé
A8: L0-07 | B8: L0 | C8: E0.2 | D8: Infrastructure sur site | E8: Tâche technique | F8: Données, fichiers et secrets sur site | G8: PostgreSQL 16, volume de fichiers derrière le port FileStore sur disque chiffré, file de jobs pg-boss (generation, export, email), secrets en fichiers, rôles de base. | H8: - Disques et volumes de fichiers chiffrés (LUKS) - Rôles app_rw, worker_rw, audit_ro et audit_purge créés avec droits minimaux - Les secrets sont montés en fichiers en lecture seule, absents des images - File d'échecs configurée avec reprise après 3 tentatives - Le port FileStore est la seule interface d'accès aux fichiers | I8: EX-NFR-01, EX-NFR-06 | J8: §1.8, §5.3, §4.19 | K8: DEVOPS | L8: Must | M8: 8 | N8: L0-06 | O8: Terminé
A9: L0-08 | B9: L0 | C9: E0.2 | D9: Infrastructure sur site | E9: Tâche technique | F9: Calcul et environnements sur site | G9: Docker Compose pour web, api et worker, trois environnements, redémarrage progressif de l'API. | H9: - Environnements dev, recette et production déployables par scripts (Compose, Ansible) - Redémarrage progressif de l'API avec contrôles de santé, sans coupure - Image worker dédiée distincte de l'API | I9: EX-NFR-02 | J9: §1.8, §5.5 | K9: DEVOPS | L9: Must | M9: 8 | N9: L0-07 | O9: Terminé
A10: L0-09 | B10: L0 | C10: E0.2 | D10: Infrastructure sur site | E10: Tâche technique | F10: Observabilité de base | G10: Logs pino avec requestId, traces OpenTelemetry, Prometheus et Grafana, alertes. | H10: - Chaque requête porte un requestId présent dans les logs - Une trace relie API, base et worker - Alertes Grafana sur file d'échecs non vide et 5xx - Les journaux techniques sont séparés de l'audit métier | I10: EX-NFR-05 | J10: §5.4 | K10: DEVOPS | L10: Should | M10: 5 | N10: L0-08 | O10: Terminé
A11: L0-10 | B11: L0 | C11: E0.3 | D11: Authentification & comptes | E11: Story | F11: Connexion, refresh et déconnexion | G11: POST /auth/login, /auth/refresh, /auth/logout avec argon2id, JWT 15 min, refresh opaque rotatif 7 jours, lecture des paramètres de sécurité. | H11: - Mots de passe hachés argon2id, longueur minimale issue des paramètres de sécurité (défaut 12) - Le refresh token tourne à chaque usage - La réutilisation d'un jeton révoqué révoque toute la famille - Le refresh est en cookie httpOnly, Secure, SameSite=Strict | I11: EX-SEC-01 | J11: §5.1, §3.4.1 | K11: BACK | L11: Must | M11: 8 | N11: L0-04 | O11: Terminé
A12: L0-11 | B12: L0 | C12: E0.3 | D12: Authentification & comptes | E12: Story | F12: Verrouillage de compte et anti-énumération | G12: Verrouillage après le nombre d'échecs configuré, pour la durée configurée. | H12: - Au dépassement du seuil (défaut 5), 401 ACCOUNT_LOCKED avec retryAfter - Le délai de réponse est identique que le compte existe ou non - Le message d'erreur est générique | I12: EX-SEC-05 | J12: §5.1 | K12: BACK | L12: Must | M12: 3 | N12: L0-10 | O12: Terminé
A13: L0-12 | B13: L0 | C13: E0.3 | D13: Authentification & comptes | E13: Story | F13: MFA TOTP | G13: Enrôlement et vérification TOTP, activable par rôle. | H13: - Un rôle listé dans mfaRoles ne peut pas finaliser sa connexion sans MFA (défaut : Administrateur) - Le code TOTP est vérifié à la connexion - MFA facultative pour les autres rôles, activable par l'Administrateur | I13: EX-SEC-06 | J13: §5.1 | K13: BACK | L13: Must | M13: 5 | N13: L0-10 | O13: Terminé
A14: L0-13 | B14: L0 | C14: E0.3 | D14: Authentification & comptes | E14: Story | F14: Paramètres de sécurité configurables | G14: Modèle ParametreSecurite (ligne unique) et API GET/PATCH /parametres/securite. | H14: - Longueur minimale, composition, expiration, historique, verrouillage, inactivité, MFA par rôle et conservation des journaux sont modifiables par l'Administrateur - Longueur minimale inférieure à 8 refusée (422) - Chaque modification écrit un audit (ancienne et nouvelle valeur) - Valeurs par défaut conformes à ST §5.1 | I14: EX-SEC-04 | J14: §5.1, §3.4.21, §2.2 | K14: BACK | L14: Must | M14: 5 | N14: L0-10, L0-23 | O14: À faire
... A131: L3-45 | B131: L3 | C131: E3.13 | D131: Imports de planification | E131: Story | F131: Import des données de planification par le Gestionnaire | G131: Imports CSV et XLSX des indisponibilités, vœux, contraintes et groupes de covoiturage. | H131: - Mêmes règles que l'import de référentiel (simulation, rapport, aucun import partiel) - Écriture réservée au Gestionnaire et à l'Administrateur | I131: EX-IMP-01 | J131: §4.9 | K131: BACK | L131: Should | M131: 5 | N131: L1-26, L3-33, L3-41, L3-03 | O131: À faire
A132: L4-01 | B132: L4 | C132: E4.1 | D132: Spike FET (S1) | E132: Spike | F132: Spike S1 : tests empiriques FET (analyse documentaire faite) | G132: L'analyse documentaire est terminée (ADR_S1_FET.md). Reste à valider sur FET 7.11.1 (Linux) avec le fichier de l'ISAMK, via s1_fet_tests.sh. | H132: - Capacité de salle contre effectif des groupes testée et résultat consigné - Codes de sortie de fet-cl documentés (succès, impossible, limite de temps, SIGTERM) - Durée d'écriture d'un résultat partiel mesurée et délai SIGKILL fixé - Emplacement et déclencheur de sigwrite confirmés - Positions imposées à 100 % sans passage à « impossible » testées - ADR-S1 passé au statut Accepté et résultats ajoutés en section 7 | I132: EX-MOT-04, EX-MOT-06 | J132: §6.1, §4.6.4 | K132: BACK | L132: Must | M132: 5 | O132: À faire
A133: L4-02 | B133: L4 | C133: E4.2 | D133: Port & adaptateur FET | E133: Story | F133: Port SchedulingEngine et modèle neutre | G133: Interface SchedulingEngine, EngineInput neutre, describeCapabilities. | H133: - Le domaine ne dépend d'aucun type FET ni Prisma - Un moteur futur n'implémente que le port | I133: EX-MOT-01, EX-PRI-01 | J133: §1.6 | K133: BACK | L133: Must | M133: 3 | N133: L0-03 | O133: À faire
A134: L4-03 | B134: L4 | C134: E4.2 | D134: Port & adaptateur FET | E134: Story | F134: Construction du fichier FET : entités | G134: Activités, enseignants (identifiants techniques), groupes, salles, créneaux, Activity Tags. | H134: - Sérialisation déterministe, identique octet à octet pour les mêmes entrées - Aucune identité en clair dans le fichier - Test golden file sur jeu de données de l'ISAMK - Périodes FET construites depuis les créneaux du semestre (jours × créneaux de 30 minutes) ; durée d'activité en nombre de créneaux | I134: EX-MOT-02 | J134: §4.6.1, §4.6.2 | K134: BACK | L134: Must | M134: 8 | N134: L4-02, L4-01, L3-09, L1-06 | O134: À faire
A135: L4-04 | B135: L4 | C135: E4.2 | D135: Port & adaptateur FET | E135: Story | F135: Construction du fichier FET : contraintes dures | G135: Pauses, indisponibilités, compatibilités salles par tag, salle imposée, liste autorisée, espacement des séances. | H135: - Chaque contrainte dure active produit son équivalent FET - Tests golden file par contrainte | I135: EX-MOT-02 | J135: §4.6.2 | K135: BACK | L135: Must | M135: 8 | N135: L4-03, L3-43, L3-08 | O135: À faire
A136: L4-05 | B136: L4 | C136: E4.2 | D136: Port & adaptateur FET | E136: Story | F136: Construction du fichier FET : contraintes souples et verrous | G136: Poids %, positions imposées pour verrous créneau, salle et activité. | H136: - Poids convertis en pourcentage FET - Verrou créneau, salle ou activité envoyé comme contrainte imposée à 100 % de poids - Test : régénération partielle sans passage à « impossible » - Les vœux sont traduits en contraintes souples à poids inférieur à 100 %, jamais 100 % - Verrou enseignant et règles APPLICATION_ONLY non envoyés | I136: EX-MOT-02, EX-VRR-01 | J136: §4.6.2, §4.14 | K136: BACK | L136: Must | M136: 8 | N136: L4-04, L3-36, L3-33 | O136: À faire
A137: L4-06 | B137: L4 | C137: E4.2 | D137: Port & adaptateur FET | E137: Story | F137: Rapport de traduction | G137: mappingReport TRADUITE, PARTIELLE, NON_TRADUITE et prévisualisation, règles traduites et règles contrôlées par l'application. | H137: - Chaque contrainte active a un statut - GET /semestres/{id}/contraintes/fet-mapping retourne le rapport - Les PARTIELLE ont une raison explicite - Le rapport de génération distingue règles traduites dans le fichier et règles contrôlées par l'application | I137: EX-MOT-03, EX-PRI-02 | J137: §4.6.3 | K137: BACK | L137: Must | M137: 5 | N137: L4-04, L3-02 | O137: À faire
A138: L4-07 | B138: L4 | C138: E4.3 | D138: Worker de génération | E138: Story | F138: Worker idempotent sur la file PostgreSQL | G138: Consommation de la file pg-boss, claim, reprise des jobs orphelins, file d'échecs. | H138: - Un job tué est repris sans doublon - File d'échecs après 3 tentatives avec alerte - Un seul job actif par semestre | I138: EX-GEN-04, EX-GEN-05 | J138: §4.6.4, §4.19 | K138: BACK | L138: Must | M138: 8 | N138: L0-07 | O138: À faire
A139: L4-08 | B139: L4 | C139: E4.3 | D139: Worker de génération | E139: Story | F139: Exécution isolée de fet-cl | G139: Sous-processus fet-cl en version épinglée 7.11.1, outputdir dédié, arrêt ordonné. | H139: - Conteneur sans réseau sortant, système de fichiers en lecture seule, non-root, limites CPU et mémoire - Arrêt par SIGTERM (écriture du résultat partiel) puis SIGKILL après un délai configurable (30 s par défaut) - Dépassement du délai : résultat partiel récupéré s'il existe - Un outputdir propre à chaque job, sorties inutiles désactivées, six graines --randomseeds10/11/12/20/21/22 fournies (--randomseedx/y refusés) - Binaire FET 7.11.1 épinglé par empreinte - Issue lue dans logs/result.txt (le code de sortie 0 couvre aussi Impossible et Time exceeded), sigwrite résiduel supprimé avant le lancement, délai de garde externe | I139: EX-MOT-04, EX-MOT-06 | J139: §4.6.4 | K139: BACK | L139: Must | M139: 8 | N139: L4-07, L4-01 | O139: À faire
A140: L4-09 | B140: L4 | C140: E4.3 | D140: Worker de génération | E140: Story | F140: Import du résultat et métriques | G140: Import du meilleur état, y compris partiel, avec séances NON_PLACEE ; échec conservé pour diagnostic. | H140: - Chaque activité est appariée par affectationKey et rang - Résultat partiel (limite de temps, génération impossible, SIGTERM) importé : séances absentes créées NON_PLACEE, statut SUCCEEDED_WITH_WARNINGS, metrics.cause renseignée - Sans sortie exploitable : FAILED avec les dernières lignes du journal, génération conservée, version de travail intacte - Conflits détectés listés après passage du ConflictEngine | I140: EX-MOT-05, EX-GEN-07 | J140: §4.6.5, §4.6.1 | K140: BACK | L140: Must | M140: 8 | N140: L4-08, L3-17 | O140: À faire
A141: L4-10 | B141: L4 | C141: E4.4 | D141: Profils de génération | E141: Story | F141: Profils de génération versionnés (modèle et API) | G141: ProfilGeneration : durée limite, préservation des verrous, versions du moteur et du constructeur, graines, poids du score ; profil par défaut du semestre. | H141: - Un profil utilisé par une génération est immuable ; le modifier crée la version suivante (CONFIG_IN_USE) - Création et modification par le Gestionnaire et l'Administrateur - Un profil par défaut peut être défini par semestre - Chaque génération enregistre le profil, sa version et une copie de ses valeurs | I141: EX-GEN-01 | J141: §2.2, §3.3 | K141: BACK | L141: Must | M141: 5 | N141: L1-01, L0-23 | O141: À faire
A142: L4-11 | B142: L4 | C142: E4.4 | D142: Profils de génération | E142: Story | F142: UI des profils de génération | G142: Création, nouvelle version, profil par défaut, poids du score. | H142: - Les poids des critères sont éditables avec leur total - Un profil utilisé est présenté en lecture seule avec « nouvelle version » | I142: EX-GEN-01 | J142: §3.3 | K142: FRONT | L142: Should | M142: 3 | N142: L4-10, L0-29 | O142: À faire
A143: L4-12 | B143: L4 | C143: E4.5 | D143: Préparation et périmètre | E143: Story | F143: Tableau de préparation du semestre | G143: GET /semestres/{id}/preparation : contrôles avant génération avec niveau, objet, règle, explication, action et lien. | H143: - Contrôles : grille, groupes valides, enseignants, salles et modules, répartitions validées (n/m), volumes couverts, verrous, exigences de salle, règles générales, indisponibilités et vœux, profil - Chaque anomalie indique son niveau (bloquant, avertissement, information), l'objet, le département, l'activité et la règle - Lien vers l'écran de correction pour chaque anomalie - Filtrable par département, enseignant, groupe, salle, activité et règle - Mêmes contrôles réutilisés par le lancement de génération | I143: EX-GEN-03 | J143: §4.12 | K143: FULL | L143: Must | M143: 8 | N143: L2-12, L1-18, L3-05, L3-36, L3-43, L4-10 | O143: À faire
A144: L4-13 | B144: L4 | C144: E4.5 | D144: Préparation et périmètre | E144: Story | F144: Périmètre explicite et empreinte | G144: GET /versions/{id}/perimetre : périmètre figé du semestre complet et empreinte ; refus du lancement si les données ont changé. | H144: - Le périmètre affiche année, semestre, départements, activités, groupes, enseignants, salles, contraintes, verrous, profil, version du jeu de règles et de l'adaptateur - Il n'est ni réductible ni modifiable en v1.0 - Le lancement exige l'empreinte affichée (409 PERIMETER_CHANGED sinon) - Le périmètre figé est enregistré avec la génération | I144: EX-GEN-02 | J144: §4.12, §3.4.5 | K144: BACK | L144: Must | M144: 5 | N144: L4-12, L3-09 | O144: À faire
... A184: L5-29 | B184: L5 | C184: E5.8 | D184: Espace Direction | E184: Story | F184: Consultation par la Direction | G184: Accès en lecture seule aux plannings publiés et archivés, exports officiels, répartition, charges, contraintes et audit. | H184: - Aucune route d'écriture accessible - Aucun accès aux versions de travail, aux générations, aux verrous ni au journal de sécurité - Navigation dédiée dans l'interface | I184: EX-ROL-04 | J184: §5.2 | K184: FULL | L184: Must | M184: 5 | N184: L3-11, L0-24, L0-29 | O184: À faire
A185: L6-01 | B185: L6 | C185: E6.1 | D185: Spike PDF/Excel (S2) | E185: Spike | F185: Spike S2 : rendu PDF/Excel | G185: Polices françaises, taille et temps de rendu. | H185: - Comparatif Playwright et bibliothèque dédiée documenté - ADR de choix et temps de rendu pour 100 pages - Rendu lisible en noir et blanc (états par icône et libellé) | I185: EX-EXP-02 | J185: §6.1 | K185: BACK | L185: Must | M185: 5 | O185: À faire
A186: L6-02 | B186: L6 | C186: E6.2 | D186: Modèles & jobs d'export | E186: Story | F186: Modèles visuels d'export versionnés | G186: ExportStyle : logo(s), en-tête, pied de page, couleurs, orientation, format, éléments affichés ; versionné et immuable une fois utilisé. | H186: - Un style utilisé n'est jamais modifié, toute évolution crée styleVersion+1 - CRUD réservé à l'Administrateur - Les logos sont stockés via FileStore - Le style par défaut utilise TAKT_logo_monochrome_deep.svg | I186: EX-EXP-04 | J186: §4.18, §2.2 | K186: BACK | L186: Must | M186: 5 | N186: L5-07 | O186: À faire
A187: L6-03 | B187: L6 | C187: E6.2 | D187: Modèles & jobs d'export | E187: Story | F187: Configurations de vue d'export versionnées | G187: ExportView : vue (groupe, enseignant, salle, formation, département, globale, charges), colonnes, ordre, feuilles, regroupements. | H187: - CRUD par le Gestionnaire et l'Administrateur - Versionné et immuable une fois utilisé - Les sept vues sont disponibles | I187: EX-EXP-04, EX-EXP-01 | J187: §4.18 | K187: BACK | L187: Must | M187: 5 | N187: L6-02 | O187: À faire
A188: L6-04 | B188: L6 | C188: E6.2 | D188: Modèles & jobs d'export | E188: Story | F188: Jobs d'export asynchrones | G188: POST /exports, statut, téléchargement par URL signée. | H188: - Les versions du style et de la vue sont enregistrées dans ExportJob - Droits : Administrateur et Gestionnaire tout ; Responsable son département ; Direction exports officiels (403 OUT_OF_SCOPE ou 422 sinon) - Échec de job avec message, relance manuelle, limite de taille - Chaque téléchargement écrit dans le journal de sécurité | I188: EX-EXP-06, EX-EXP-05 | J188: §3.4.14, §4.18, §4.19 | K188: BACK | L188: Must | M188: 8 | N188: L6-03, L0-07, L4-07, L0-18 | O188: À faire
A189: L6-05 | B189: L6 | C189: E6.2 | D189: Modèles & jobs d'export | E189: Story | F189: Brouillon, officiel, grille Ramadan et avertissements | G189: Export filigrané pour version non publiée, officiel pour PUBLIE ou ARCHIVE, choix de grille, avertissements acceptés. | H189: - Export officiel refusé hors PUBLIE ou ARCHIVE - Export brouillon : réservé aux versions non publiées (422 sur une version PUBLIE ou ARCHIVE), filigrane BROUILLON (Deep, opacité 0,1, -45°, répété) et numéro de version ; le filigrane n'apparaît jamais sur une version publiée - Export officiel : numéro de version, date de publication, grille utilisée et avertissements acceptés en pied de page - La grille Ramadan figée de la version est utilisée pour l'export officiel - Régénération d'un export historique avec les versions enregistrées | I189: EX-EXP-05, EX-CAL-04 | J189: §4.18, §4.1.1.1 | K189: BACK | L189: Must | M189: 5 | N189: L6-04, L3-39 | O189: À faire
A190: L6-06 | B190: L6 | C190: E6.3 | D190: Rendus XLSX/PDF | E190: Story | F190: Rendu XLSX | G190: ExcelJS : grilles par groupe, enseignant, salle, formation, département et vue globale ; structure configurable. | H190: - Grille jours/créneaux fidèle à la version - Colonnes, feuilles, ordre et regroupements selon la configuration de vue - Plusieurs objets par classeur | I190: EX-EXP-03 | J190: §4.18 | K190: BACK | L190: Must | M190: 8 | N190: L6-04 | O190: À faire
A191: L6-07 | B191: L6 | C191: E6.3 | D191: Rendus XLSX/PDF | E191: Story | F191: Rendu PDF | G191: HTML vers PDF (Playwright/Chromium), A4 ou A3, logo, orientation, couleurs, locale française. | H191: - Polices françaises auto-hébergées rendues correctement - Export de 100 pages < 60 s - États lisibles en noir et blanc (icône et libellé en plus de la couleur) - Le modèle visuel détermine en-tête, pied de page, couleurs et format - Impression monochrome selon export.print_monochrome des tokens (encres #000/#333/#666, bordure #808080) ; logo imprimé à 30 mm minimum (master), 20 mm (compact), 6 mm (symbole) | I191: EX-EXP-02, EX-NFR-04 | J191: §4.18, §5.4 | K191: BACK | L191: Must | M191: 13 | N191: L6-04, L6-01, L0-05 | O191: À faire
A192: L6-08 | B192: L6 | C192: E6.3 | D192: Rendus XLSX/PDF | E192: Story | F192: Export des charges | G192: Volume brut, charge calculée, charge de référence, service dû, écart et heures supplémentaires par enseignant et département. | H192: - Valeurs identiques à celles du snapshot de la version - Heures supplémentaires et plafond mis en évidence - Le Responsable n'exporte que son département | I192: EX-EXP-01, EX-EXP-06 | J192: §4.2, §4.18 | K192: BACK | L192: Should | M192: 5 | N192: L6-04, L2-10 | O192: À faire
A193: L6-09 | B193: L6 | C193: E6.4 | D193: UI exports | E193: Story | F193: UI exports | G193: Choix de la vue, du style, du périmètre, de la grille et du mode ; suivi et téléchargement. | H193: - Suivi de statut du job - Téléchargement via URL signée - Les choix proposés dépendent du rôle | I193: EX-EXP-05, EX-EXP-06 | J193: §3.3 | K193: FRONT | L193: Must | M193: 5 | N193: L6-04, L0-29 | O193: À faire
A194: L6-10 | B194: L6 | C194: E6.4 | D194: UI exports | E194: Story | F194: UI modèles visuels et configurations de vue | G194: Édition des styles (Administrateur) et des vues (Gestionnaire et Administrateur) avec aperçu. | H194: - Aperçu avant enregistrement - Un modèle utilisé se duplique en nouvelle version - Seul l'Administrateur modifie les styles | I194: EX-EXP-04 | J194: §4.18 | K194: FRONT | L194: Should | M194: 5 | N194: L6-02, L6-03, L0-29 | O194: À faire
A195: L7-01 | B195: L7 | C195: E7.1 | D195: Clôture & archivage | E195: Story | F195: Clôture d'année avec confirmation | G195: POST /annees/{id}/transitions CLOTURER avec confirmation par code de l'année. | H195: - 422 CONFIRMATION_MISMATCH si la confirmation diffère du code de l'année - Clôture refusée (422) si une version est EN_VALIDATION - Versions non publiées archivées avec le motif « clôture » - Aucune action de réouverture n'existe - Audit de la clôture (closedAt, closedBy) | I195: EX-CAL-05 | J195: §4.1.3, §3.4.15 | K195: BACK | L195: Must | M195: 5 | N195: L1-02, L5-01 | O195: À faire
...

Sheet Lots
A1: Lot | B1: Périmètre | C1: Tickets | D1: Points | E1: Points terminés
A2: L0 | B2: Socle : monorepo, CI/CD, infrastructure sur site, authentification, sécurité, RBAC, audit, socle API et web | C2: =COUNTIF(Tickets!$B$2:$B$211,A2) | D2: =SUMIF(Tickets!$B$2:$B$211,A2,Tickets!$M$2:$M$211) | E2: =SUMIFS(Tickets!$M$2:$M$211,Tickets!$B$2:$B$211,A2,Tickets!$O$2:$O$211,"Terminé")
A3: L1 | B3: Années, semestres, référentiel, ressources, grille horaire, Ramadan, imports | C3: =COUNTIF(Tickets!$B$2:$B$211,A3) | D3: =SUMIF(Tickets!$B$2:$B$211,A3,Tickets!$M$2:$M$211) | E3: =SUMIFS(Tickets!$M$2:$M$211,Tickets!$B$2:$B$211,A3,Tickets!$O$2:$O$211,"Terminé")
A4: L2 | B4: Répartition pédagogique, charge paramétrable, snapshots, vue annuelle | C4: =COUNTIF(Tickets!$B$2:$B$211,A4) | D4: =SUMIF(Tickets!$B$2:$B$211,A4,Tickets!$M$2:$M$211) | E4: =SUMIFS(Tickets!$M$2:$M$211,Tickets!$B$2:$B$211,A4,Tickets!$O$2:$O$211,"Terminé")
A5: L3 | B5: Contraintes, versions, séances, conflict-engine, éditeur manuel, verrous, avertissements | C5: =COUNTIF(Tickets!$B$2:$B$211,A5) | D5: =SUMIF(Tickets!$B$2:$B$211,A5,Tickets!$M$2:$M$211) | E5: =SUMIFS(Tickets!$M$2:$M$211,Tickets!$B$2:$B$211,A5,Tickets!$O$2:$O$211,"Terminé")
A6: L4 | B6: Génération FET : port, profils, worker, périmètre, préparation, comparaison, score, adoption | C6: =COUNTIF(Tickets!$B$2:$B$211,A6) | D6: =SUMIF(Tickets!$B$2:$B$211,A6,Tickets!$M$2:$M$211) | E6: =SUMIFS(Tickets!$M$2:$M$211,Tickets!$B$2:$B$211,A6,Tickets!$O$2:$O$211,"Terminé")
A7: L5 | B7: Workflow, impact, notifications, circuit configurable, tableau de bord | C7: =COUNTIF(Tickets!$B$2:$B$211,A7) | D7: =SUMIF(Tickets!$B$2:$B$211,A7,Tickets!$M$2:$M$211) | E7: =SUMIFS(Tickets!$M$2:$M$211,Tickets!$B$2:$B$211,A7,Tickets!$O$2:$O$211,"Terminé")
A8: L6 | B8: Exports PDF et Excel | C8: =COUNTIF(Tickets!$B$2:$B$211,A8) | D8: =SUMIF(Tickets!$B$2:$B$211,A8,Tickets!$M$2:$M$211) | E8: =SUMIFS(Tickets!$M$2:$M$211,Tickets!$B$2:$B$211,A8,Tickets!$O$2:$O$211,"Terminé")
A9: L7 | B9: Clôture, durcissement, performance, exploitation, recette, mise en production | C9: =COUNTIF(Tickets!$B$2:$B$211,A9) | D9: =SUMIF(Tickets!$B$2:$B$211,A9,Tickets!$M$2:$M$211) | E9: =SUMIFS(Tickets!$M$2:$M$211,Tickets!$B$2:$B$211,A9,Tickets!$O$2:$O$211,"Terminé")
A10: Total | C10: =SUM(C2:C9) | D10: =SUM(D2:D9) | E10: =SUM(E2:E9)

Sheet Epics
A1: Epic ID | B1: Lot | C1: Epic | D1: Tickets | E1: Points
A2: E0.1 | B2: L0 | C2: Monorepo & CI/CD | D2: =COUNTIF(Tickets!$C$2:$C$211,A2) | E2: =SUMIF(Tickets!$C$2:$C$211,A2,Tickets!$M$2:$M$211)
A3: E0.2 | B3: L0 | C3: Infrastructure sur site | D3: =COUNTIF(Tickets!$C$2:$C$211,A3) | E3: =SUMIF(Tickets!$C$2:$C$211,A3,Tickets!$M$2:$M$211)
A4: E0.3 | B4: L0 | C4: Authentification & comptes | D4: =COUNTIF(Tickets!$C$2:$C$211,A4) | E4: =SUMIF(Tickets!$C$2:$C$211,A4,Tickets!$M$2:$M$211)
A5: E0.4 | B5: L0 | C5: RBAC avec portée | D5: =COUNTIF(Tickets!$C$2:$C$211,A5) | E5: =SUMIF(Tickets!$C$2:$C$211,A5,Tickets!$M$2:$M$211)
A6: E0.5 | B6: L0 | C6: Audit append-only | D6: =COUNTIF(Tickets!$C$2:$C$211,A6) | E6: =SUMIF(Tickets!$C$2:$C$211,A6,Tickets!$M$2:$M$211)
A7: E0.6 | B7: L0 | C7: Socle API | D7: =COUNTIF(Tickets!$C$2:$C$211,A7) | E7: =SUMIF(Tickets!$C$2:$C$211,A7,Tickets!$M$2:$M$211)
A8: E0.7 | B8: L0 | C8: Socle web | D8: =COUNTIF(Tickets!$C$2:$C$211,A8) | E8: =SUMIF(Tickets!$C$2:$C$211,A8,Tickets!$M$2:$M$211)
A9: E1.1 | B9: L1 | C9: Années & semestres | D9: =COUNTIF(Tickets!$C$2:$C$211,A9) | E9: =SUMIF(Tickets!$C$2:$C$211,A9,Tickets!$M$2:$M$211)
A10: E1.2 | B10: L1 | C10: Structure académique | D10: =COUNTIF(Tickets!$C$2:$C$211,A10) | E10: =SUMIF(Tickets!$C$2:$C$211,A10,Tickets!$M$2:$M$211)
A11: E1.3 | B11: L1 | C11: Enseignants, grades & décharges | D11: =COUNTIF(Tickets!$C$2:$C$211,A11) | E11: =SUMIF(Tickets!$C$2:$C$211,A11,Tickets!$M$2:$M$211)
A12: E1.4 | B12: L1 | C12: Salles & équipements | D12: =COUNTIF(Tickets!$C$2:$C$211,A12) | E12: =SUMIF(Tickets!$C$2:$C$211,A12,Tickets!$M$2:$M$211)
A13: E1.5 | B13: L1 | C13: Grille horaire & indisponibilités | D13: =COUNTIF(Tickets!$C$2:$C$211,A13) | E13: =SUMIF(Tickets!$C$2:$C$211,A13,Tickets!$M$2:$M$211)
... A61: E7.5 | B61: L7 | C61: Recette & mise en production | D61: =COUNTIF(Tickets!$C$2:$C$211,A61) | E61: =SUMIF(Tickets!$C$2:$C$211,A61,Tickets!$M$2:$M$211)
A62: Total | D62: =SUM(D2:D61) | E62: =SUM(E2:E61)
